<robot name="uf850">
  <link name="base_link">
    <visual>
      <origin xyz="0 0 0" rpy="0 0 0"/>
      <geometry>
        <mesh filename="meshes/link_base.stl" scale="1.0 1.0 1.0"/>
      </geometry>
      <material name="LightGrey">
        <color rgba="0.9 0.9 0.9 1.0"/>
      </material>
    </visual>
    <inertial>
      <mass value="4.0"/>
      <origin rpy="0 0 0" xyz="0.0 0.0 0.0"/>
      <inertia ixx="0.00443333156" ixy="0.0" ixz="0.0" iyy="0.00443333156" iyz="0.0" izz="0.0072"/>
    </inertial>
  </link>

  <link name="link1">
    <visual>
      <origin xyz="0 0 0.2" rpy="0 0 0"/>
      <geometry>
        <mesh filename="meshes/link1.stl" scale="1.0 1.0 1.0"/>
      </geometry>
      <material name="LightGrey">
        <color rgba="0.9 0.9 0.9 1.0"/>
      </material>
    </visual>
    <inertial>
      <mass value="3.7"/>
      <origin rpy="0 0 0" xyz="0.0 0.0 0.0"/>
      <inertia ixx="0.010267495893" ixy="0.0" ixz="0.0" iyy="0.010267495893" iyz="0.0" izz="0.00666"/>
    </inertial>
  </link>

  <joint name="base_to_link1" type="revolute">
    <axis xyz="0 0 1"/>
    <parent link="base_link"/>
    <child link="link1"/>
    <origin xyz="0 0 0.15" rpy="0 0 0"/>
    <limit effort="150.0" lower="-6.28318530718" upper="6.28318530718" velocity="3.15"/>
    <dynamics damping="0.0" friction="0.0"/>
  </joint>

  <link name="link2">
    <visual>
      <origin xyz="0 0 0" rpy="0 -1.57 1.57"/>
      <geometry>
        <mesh filename="meshes/link2.stl" scale="1.0 1.0 1.0"/>
      </geometry>
      <material name="LightGrey">
        <color rgba="0.9 0.9 0.9 1.0"/>
      </material>
    </visual>
    <inertial>
      <mass value="8.393"/>
      <origin rpy="0 0 0" xyz="0.0 0.0 0.28"/>
      <inertia ixx="0.22689067591" ixy="0.0" ixz="0.0" iyy="0.22689067591" iyz="0.0" izz="0.0151074"/>
    </inertial>
  </link>

  <joint name="link1_to_link2" type="revolute">
    <parent link="link1"/>
    <child link="link2"/>
    <origin xyz="0 0 0.2" rpy="0 0 0"/>
    <axis xyz="0 1 0"/>
    <limit effort="150.0" lower="-6.28318530718" upper="6.28318530718" velocity="3.15"/>
    <dynamics damping="0.0" friction="0.0"/>
  </joint>

  <link name="link3">
    <visual>
      <origin xyz="0 0 0" rpy="0 0 -1.57"/>
      <geometry>
        <mesh filename="meshes/link3.stl" scale="1.0 1.0 1.0"/>
      </geometry>
      <material name="LightGrey">
        <color rgba="0.9 0.9 0.9 1.0"/>
      </material>
    </visual>
    <inertial>
      <mass value="2.275"/>
      <origin rpy="0 0 0" xyz="0.0 0.0 0.25"/>
      <inertia ixx="0.049443313556" ixy="0.0" ixz="0.0" iyy="0.049443313556" iyz="0.0" izz="0.004095"/>
    </inertial>
  </link>

  <joint name="link2_to_link3" type="revolute">
    <axis xyz="0 0 1"/>
    <parent link="link2"/>
    <child link="link3"/>
    <origin xyz="0 0 0.39" rpy="1.57 1.57 3.14"/>
    <limit effort="150.0" lower="-3.14159265359" upper="3.14159265359" velocity="3.15"/>
    <dynamics damping="0.0" friction="0.0"/>
  </joint>

  <link name="link4">
    <visual>
      <origin xyz="0.3 0 0" rpy="1.57 -1.57 1.57"/>
      <geometry>
        <mesh filename="meshes/link4.stl" scale="1.0 1.0 1.0"/>
      </geometry>
      <material name="LightGrey">
        <color rgba="0.9 0.9 0.9 1.0"/>
      </material>
    </visual>
    <inertial>
      <mass value="1.219"/>
      <origin rpy="0 0 0" xyz="0.0 0.0 0.0"/>
      <inertia ixx="0.111172755531" ixy="0.0" ixz="0.0" iyy="0.111172755531" iyz="0.0" izz="0.21942"/>
    </inertial>
  </link>

  <joint name="link3_to_link4" type="revolute">
    <axis xyz="1 0 0"/>
    <parent link="link3"/>
    <child link="link4"/>
    <origin xyz="0.1 -0.15 0" rpy="1.57 0 0"/>
    <limit effort="28.0" lower="-6.28318530718" upper="6.28318530718" velocity="3.2"/>
    <dynamics damping="0.0" friction="0.0"/>
  </joint>

  <link name="link5">
    <visual>
      <origin xyz="0 0.1 0" rpy="1.57 1.57 3.14"/>
      <geometry>
        <mesh filename="meshes/link5.stl" scale="1.0 1.0 1.0"/>
      </geometry>
      <material name="LightGrey">
        <color rgba="0.9 0.9 0.9 1.0"/>
      </material>
    </visual>
    <inertial>
      <mass value="1.219"/>
      <origin rpy="0 0 0" xyz="0.0 0.0 0.0"/>
      <inertia ixx="0.111172755531" ixy="0.0" ixz="0.0" iyy="0.111172755531" iyz="0.0" izz="0.21942"/>
    </inertial>
  </link>

  <joint name="link4_to_link5" type="revolute">
    <axis xyz="0 1 0"/>
    <parent link="link4"/>
    <child link="link5"/>
    <origin xyz="0.3 0.1 0" rpy="3.14 0 0"/>
    <limit effort="28.0" lower="-6.28318530718" upper="6.28318530718" velocity="3.2"/>
    <dynamics damping="0.0" friction="0.0"/>
  </joint>

  <link name="link6">
    <visual>
      <origin xyz="0 0 0" rpy="0 0 0"/>
      <geometry>
        <mesh filename="meshes/link6.stl" scale="1.0 1.0 1.0"/>
      </geometry>
      <material name="LightGrey">
        <color rgba="0.9 0.9 0.9 1.0"/>
      </material>
    </visual>
    <inertial>
      <mass value="0.1879"/>
      <origin rpy="0 0 0" xyz="0.0 0.0 0.0"/>
      <inertia ixx="0.0171364731454" ixy="0.0" ixz="0.0" iyy="0.0171364731454" iyz="0.0" izz="0.033822"/>
    </inertial>
  </link>

  <joint name="link5_to_link6" type="revolute">
    <axis xyz="0 0 1"/>
    <parent link="link5"/>
    <child link="link6"/>
    <origin xyz="0.0895 0.1 0" rpy="0 1.57 0"/>
    <limit effort="28.0" lower="-6.28318530718" upper="6.28318530718" velocity="3.2"/>
    <dynamics damping="0.0" friction="0.0"/>
  </joint>

  <link name="ee_link">
    <!-- <visual>
    <geometry>
      <box size="0.05 0.05 0.05"/>
    </geometry>
    <material name="blue">
      <color rgba="0.1 0.1 0.8 1"/>
    </material>
  </visual> -->
    <inertial>
      <mass value="0.01"/>
      <inertia ixx="0" ixy="0" ixz="0" iyy="0" iyz="0" izz="0"/>
    </inertial>
  </link>

  <joint name="ee_fixed_joint" type="fixed">
    <parent link="link6"/>
    <child link="ee_link"/>
    <origin xyz="0 0 0" rpy="0 0 0"/>
  </joint>

  <link name="tool_tip">
    <inertial>
      <mass value="0.0"/>
      <origin rpy="0 0 0" xyz="0.0 0.0 0.0"/>
      <inertia ixx="0.0" ixy="0.0" ixz="0.0" iyy="0.0" iyz="0.0" izz="0.0"/>
    </inertial>
    <!-- <visual>
      <geometry>
        <box size="0.01 0.01 0.01"/>
      </geometry>
      <material name="DarkGrey"/>
      <origin rpy="0 0 0" xyz="0 0 0"/>
    </visual> -->
  </link>
  <joint name="tool0_fixed_joint-tool_tip" type="fixed">
    <origin rpy="0 0 0" xyz="0 0 0.11"/>
    <parent link="ee_link"/>
    <child link="tool_tip"/>
  </joint>

</robot>
